<?xml version="1.0" ?>
<robot name="mini_cheetah" xmlns:xacro="http://ros.org/wiki/xacro">
    <link name="trunk">
        <inertial>
            <mass value="3.3"/>
            <origin xyz="0.0 0.0 0.0"/>
            <inertia ixx="0.011253" ixy="0" ixz="0" iyy="0.036203" iyz="0" izz="0.042673"/>
        </inertial>
        <visual>
            <geometry>
                <mesh filename="../meshes/mini_body.stl"/>
            </geometry>
            <origin rpy="0.0 0.0 0.0" xyz="0.0 0.0 0.0"/>
        </visual>
        <collision>
            <geometry>
                <mesh filename="../meshes/mini_body.stl"/>
            </geometry>
            <origin rpy="0 0 0" xyz="0 0 0"/>
        </collision>
    </link>

    <joint name="1_FR_hip_joint" type="revolute">
        <axis xyz="1 0 0"/>
        <origin rpy="0 0 0" xyz="0.19 -0.049 0.0"/>
        <parent link="trunk"/>
        <child link="1_FR_hip"/>
        <dynamics damping="0.0" friction="0.0"/>
        <limit effort="40" lower="-6.28" upper="6.28" velocity="30.1"/>
    </joint>
    <link name="1_FR_hip">
        <inertial>
            <mass value="0.54"/>
            <origin xyz="0.0 0.036 0."/>
            <inertia ixx="0.000381" ixy="0.000058" ixz="0.00000045" 
                iyy="0.000560" iyz="0.00000095" izz="0.000444"/>
        </inertial>
        <visual>
            <geometry>
                <mesh filename="../meshes/mini_abad.stl"/>
            </geometry>
            <origin rpy="3.141592 0.0 1.5708" xyz="-0.055 0.0 0.0"/>
        </visual>
        <collision>
            <geometry>
                <mesh filename="../meshes/mini_abad.stl"/>
            </geometry>
            <origin rpy="3.141592 0 1.5708" xyz="-0.055 0 0"/>
        </collision>
    </link>

    <joint name="1_FR_thigh_joint" type="revolute">
        <axis xyz="0 1 0"/>
        <origin rpy="0.0 0.0 0.0" xyz="0.0 -0.062 0.00"/>
        <parent link="1_FR_hip"/>
        <child link="1_FR_thigh"/>
        <dynamics damping="0.0" friction="0.0"/>
        <limit effort="40" lower="-6.28" upper="6.28" velocity="30.1"/>
    </joint>
    <link name="1_FR_thigh">
        <inertial>
            <mass value="0.634"/>
            <origin xyz="0.0 0.016 -0.02"/>
            <inertia ixx="0.001983" ixy="0.000245" ixz="0.000013" 
                iyy="0.002103" iyz="0.0000015" izz="0.000408"/>
        </inertial>
        <visual>
            <geometry>
                <mesh filename="../meshes/mini_upper_link.stl"/>
            </geometry>
            <origin rpy="0.0 -1.5708 0.0" xyz="0.0 0.0 0.0"/>
        </visual>
        <collision>
            <geometry>
                <mesh filename="../meshes/mini_upper_link.stl"/>
            </geometry>
            <origin rpy="0 -1.5708 0" xyz="0 0 0"/>
        </collision>
    </link>

    <joint name="1_FR_calf_joint" type="revolute">
        <axis xyz="0 1 0"/>
        <origin rpy="0.0 0 0.0" xyz="0.0 0.0 -0.209"/>
        <parent link="1_FR_thigh"/>
        <child link="1_FR_calf"/>
        <dynamics damping="0.0" friction="0.0"/>
        <limit effort="40" lower="-6.28" upper="6.28" velocity="30.1"/>
    </joint>
    <link name="1_FR_calf">
        <inertial>
            <mass value="0.064"/>
            <origin xyz="0.0 0.0 -0.209"/>
            <inertia ixx="0.000245" ixy="0" ixz="0.0" iyy="0.000248" iyz="0" izz="0.000006"/>
        </inertial>
        <visual>
            <geometry>
                <mesh filename="../meshes/mini_lower_link.stl"/>
            </geometry>
            <origin rpy="0.0 3.141592 0.0" xyz="0.0 0.0 0.0"/>
        </visual>
        <collision>
            <geometry>
                <mesh filename="../meshes/mini_lower_link.stl"/>
            </geometry>
            <origin rpy="0 3.141592 0" xyz="0 0 0"/>
        </collision>
    </link>
    <link name="1_FR_foot">
        <visual>
        <origin rpy="0 0 0" xyz="0 0 0"/>
        <geometry>
            <sphere radius="0.015"/>
        </geometry>
        <material name="darkgray"/>
        </visual>
        <collision>
        <origin rpy="0 0 0" xyz="0 0 0"/>
        <geometry>
            <sphere radius="0.015"/>
        </geometry>
        </collision>
        <inertial>
        <mass value="0.15"/>
        <inertia ixx="0.000025" ixy="0" ixz="0" iyy="0.000025" iyz="0" izz="0.000025"/>
        </inertial>
    </link>
    <joint name="1_FR_foot_fixed" type="fixed"  dont_collapse="true">
        <parent link="1_FR_calf"/>
        <child link="1_FR_foot"/>
        <origin xyz="0 0 -0.18"/>
        <dynamics damping="0.0" friction="0.0"/>
    </joint>

 
    <joint name="2_FL_hip_joint" type="revolute">
        <axis xyz="1 0 0"/>
        <origin rpy="0 0 0" xyz="0.19 0.049 0.0"/>
        <parent link="trunk"/>
        <child link="2_FL_hip"/>
        <dynamics damping="0.0" friction="0.0"/>
        <limit effort="40" lower="-6.28" upper="6.28" velocity="30.1"/>
    </joint>
    <link name="2_FL_hip">
        <inertial>
            <mass value="0.54"/>
            <origin xyz="0.0 0.036 0."/>
            <inertia ixx="0.000381" ixy="0.000058" ixz="0.00000045" 
                iyy="0.000560" iyz="0.00000095" izz="0.000444"/>
        </inertial>
        <visual>
            <geometry>
                <mesh filename="../meshes/mini_abad.stl"/>
            </geometry>
            <origin rpy="0. 0. -1.5708" xyz="-0.055 0.0 0.0"/>
        </visual>
        <collision>
            <geometry>
                <mesh filename="../meshes/mini_abad.stl"/>
            </geometry>
            <origin rpy="0 0 -1.5708" xyz="-0.055 0 0"/>
        </collision>
    </link>

    <joint name="2_FL_thigh_joint" type="revolute">
        <axis xyz="0 1 0"/>
        <origin rpy="0.0 0.0 0.0" xyz="0.0 0.062 0.00"/>
        <parent link="2_FL_hip"/>
        <child link="2_FL_thigh"/>
        <dynamics damping="0.0" friction="0.0"/>
        <limit effort="40" lower="-6.28" upper="6.28" velocity="30.1"/>
    </joint>
    <link name="2_FL_thigh">
        <inertial>
            <mass value="0.634"/>
            <origin xyz="0.0 0.016 -0.02"/>
            <inertia ixx="0.001983" ixy="0.000245" ixz="0.000013" 
                iyy="0.002103" iyz="0.0000015" izz="0.000408"/>
        </inertial>
        <visual>
            <geometry>
                <mesh filename="../meshes/mini_upper_link.stl"/>
            </geometry>
            <origin rpy="0.0 -1.5708 0.0" xyz="0.0 0.0 0.0"/>
        </visual>
        <collision>
            <geometry>
                <mesh filename="../meshes/mini_upper_link.stl"/>
            </geometry>
            <origin rpy="0 -1.5708 0" xyz="0 0 0"/>
        </collision>
    </link>

    <joint name="2_FL_calf_joint" type="revolute">
        <axis xyz="0 1 0"/>
        <origin rpy="0.0 0 0.0" xyz="0.0 0.0 -0.209"/>
        <parent link="2_FL_thigh"/>
        <child link="2_FL_calf"/>
        <dynamics damping="0.0" friction="0.0"/>
        <limit effort="40" lower="-6.28" upper="6.28" velocity="30.1"/>
    </joint>
    <link name="2_FL_calf">
        <inertial>
            <mass value="0.064"/>
            <origin xyz="0.0 0.0 -0.209"/>
            <inertia ixx="0.000245" ixy="0" ixz="0.0" iyy="0.000248" iyz="0" izz="0.000006"/>
        </inertial>
        <visual>
            <geometry>
                <mesh filename="../meshes/mini_lower_link.stl"/>
            </geometry>
            <origin rpy="0.0 3.141592 0.0" xyz="0.0 0.0 0.0"/>
        </visual>
        <collision>
            <geometry>
                <mesh filename="../meshes/mini_lower_link.stl"/>
            </geometry>
            <origin rpy="0 3.141592 0" xyz="0 0 0"/>
        </collision>
    </link>
    <link name="2_FL_foot">
        <visual>
        <origin rpy="0 0 0" xyz="0 0 0"/>
        <geometry>
            <sphere radius="0.015"/>
        </geometry>
        <material name="darkgray"/>
        </visual>
        <collision>
        <origin rpy="0 0 0" xyz="0 0 0"/>
        <geometry>
            <sphere radius="0.015"/>
        </geometry>
        </collision>
        <inertial>
        <mass value="0.15"/>
        <inertia ixx="0.000025" ixy="0" ixz="0" iyy="0.000025" iyz="0" izz="0.000025"/>
        </inertial>
    </link>
    <joint name="2_FL_foot_fixed" type="fixed" dont_collapse="true">
        <parent link="2_FL_calf"/>
        <child link="2_FL_foot"/>
        <origin xyz="0 0 -0.18"/>
        <dynamics damping="0.0" friction="0.0"/>
    </joint>


    <joint name="3_RR_hip_joint" type="revolute">
        <axis xyz="1 0 0"/>
        <origin rpy="0 0 0" xyz="-0.19 -0.049 0.0"/>
        <parent link="trunk"/>
        <child link="3_RR_hip"/>
        <dynamics damping="0.0" friction="0.0"/>
        <limit effort="40" lower="-6.28" upper="6.28" velocity="30.1"/>
    </joint>
    <link name="3_RR_hip">
        <inertial>
            <mass value="0.54"/>
            <origin xyz="0.0 0.036 0."/>
            <inertia ixx="0.000381" ixy="0.000058" ixz="0.00000045" 
                iyy="0.000560" iyz="0.00000095" izz="0.000444"/>
        </inertial>
        <visual>
            <geometry>
                <mesh filename="../meshes/mini_abad.stl"/>
            </geometry>
            <origin rpy="0.0 0.0 1.5708" xyz="0.055 0.0 0.0"/>
        </visual>
        <collision>
            <geometry>
                <mesh filename="../meshes/mini_abad.stl"/>
            </geometry>
            <origin rpy="0 0 1.5708" xyz="0.055 0 0"/>
        </collision>
    </link>

    <joint name="3_RR_thigh_joint" type="revolute">
        <axis xyz="0 1 0"/>
        <origin rpy="0.0 0.0 0.0" xyz="0.0 -0.062 0.00"/>
        <parent link="3_RR_hip"/>
        <child link="3_RR_thigh"/>
        <dynamics damping="0.0" friction="0.0"/>
        <limit effort="40" lower="-6.28" upper="6.28" velocity="30.1"/>
    </joint>
    <link name="3_RR_thigh">
        <inertial>
            <mass value="0.634"/>
            <origin xyz="0.0 0.016 -0.02"/>
            <inertia ixx="0.001983" ixy="0.000245" ixz="0.000013" 
                iyy="0.002103" iyz="0.0000015" izz="0.000408"/>
        </inertial>
        <visual>
            <geometry>
                <mesh filename="../meshes/mini_upper_link.stl"/>
            </geometry>
            <origin rpy="0.0 -1.5708 0.0" xyz="0.0 0.0 0.0"/>
        </visual>
        <collision>
            <geometry>
                <mesh filename="../meshes/mini_upper_link.stl"/>
            </geometry>
            <origin rpy="0 -1.5708 0" xyz="0 0 0"/>
        </collision>
    </link>

    <joint name="3_RR_calf_joint" type="revolute">
        <axis xyz="0 1 0"/>
        <origin rpy="0.0 0 0.0" xyz="0.0 0.0 -0.209"/>
        <parent link="3_RR_thigh"/>
        <child link="3_RR_calf"/>
        <dynamics damping="0.0" friction="0.0"/>
        <limit effort="40" lower="-6.28" upper="6.28" velocity="30.1"/>
    </joint>
    <link name="3_RR_calf">
        <inertial>
            <mass value="0.064"/>
            <origin xyz="0.0 0.0 -0.209"/>
            <inertia ixx="0.000245" ixy="0" ixz="0.0" iyy="0.000248" iyz="0" izz="0.000006"/>
        </inertial>
        <visual>
            <geometry>
                <mesh filename="../meshes/mini_lower_link.stl"/>
            </geometry>
            <origin rpy="0.0 3.141592 0.0" xyz="0.0 0.0 0.0"/>
        </visual>
        <collision>
            <geometry>
                <mesh filename="../meshes/mini_lower_link.stl"/>
            </geometry>
            <origin rpy="0 3.141592 0" xyz="0 0 0"/>
        </collision>
    </link>
    <link name="3_RR_foot">
        <visual>
        <origin rpy="0 0 0" xyz="0 0 0"/>
        <geometry>
            <sphere radius="0.015"/>
        </geometry>
        <material name="darkgray"/>
        </visual>
        <collision>
        <origin rpy="0 0 0" xyz="0 0 0"/>
        <geometry>
            <sphere radius="0.015"/>
        </geometry>
        </collision>
        <inertial>
        <mass value="0.15"/>
        <inertia ixx="0.000025" ixy="0" ixz="0" iyy="0.000025" iyz="0" izz="0.000025"/>
        </inertial>
    </link>
    <joint name="3_RR_foot_fixed" type="fixed" dont_collapse="true">
        <parent link="3_RR_calf"/>
        <child link="3_RR_foot"/>
        <origin xyz="0 0 -0.18"/>
        <dynamics damping="0.0" friction="0.0"/>
    </joint>


    <joint name="4_RL_hip_joint" type="revolute">
        <axis xyz="1 0 0"/>
        <origin rpy="0 0 0" xyz="-0.19 0.049 0.0"/>
        <parent link="trunk"/>
        <child link="4_RL_hip"/>
        <dynamics damping="0.0" friction="0.0"/>
        <limit effort="40" lower="-6.28" upper="6.28" velocity="30.1"/>
    </joint>
    <link name="4_RL_hip">
        <inertial>
            <mass value="0.54"/>
            <origin xyz="0.0 0.036 0."/>
            <inertia ixx="0.000381" ixy="0.000058" ixz="0.00000045" 
                iyy="0.000560" iyz="0.00000095" izz="0.000444"/>
        </inertial>
        <visual>
            <geometry>
                <mesh filename="../meshes/mini_abad.stl"/>
            </geometry>
            <origin rpy="3.141592 0.0 -1.5708" xyz="0.055 0.0 0.0"/>
        </visual>
        <collision>
            <geometry>
                <mesh filename="../meshes/mini_abad.stl"/>
            </geometry>
            <origin rpy="3.141592 0 -1.5708" xyz="0.055 0 0"/>
        </collision>
    </link>

    <joint name="4_RL_thigh_joint" type="revolute">
        <axis xyz="0 1 0"/>
        <origin rpy="0.0 0.0 0.0" xyz="0.0 0.062 0.00"/>
        <parent link="4_RL_hip"/>
        <child link="4_RL_thigh"/>
        <dynamics damping="0.0" friction="0.0"/>
        <limit effort="40" lower="-6.28" upper="6.28" velocity="30.1"/>
    </joint>
    <link name="4_RL_thigh">
        <inertial>
            <mass value="0.634"/>
            <origin xyz="0.0 0.016 -0.02"/>
            <inertia ixx="0.001983" ixy="0.000245" ixz="0.000013" 
                iyy="0.002103" iyz="0.0000015" izz="0.000408"/>
        </inertial>
        <visual>
            <geometry>
                <mesh filename="../meshes/mini_upper_link.stl"/>
            </geometry>
            <origin rpy="0.0 -1.5708 0.0" xyz="0.0 0.0 0.0"/>
        </visual>
        <collision>
            <geometry>
                <mesh filename="../meshes/mini_upper_link.stl"/>
            </geometry>
            <origin rpy="0 -1.5708 0" xyz="0 0 0"/>
        </collision>
    </link>

    <joint name="4_RL_calf_joint" type="revolute">
        <axis xyz="0 1 0"/>
        <origin rpy="0.0 0 0.0" xyz="0.0 0.0 -0.209"/>
        <parent link="4_RL_thigh"/>
        <child link="4_RL_calf"/>
        <dynamics damping="0.0" friction="0.0"/>
        <limit effort="40" lower="-6.28" upper="6.28" velocity="30.1"/>
    </joint>
    <link name="4_RL_calf">
        <inertial>
            <mass value="0.064"/>
            <origin xyz="0.0 0.0 -0.209"/>
            <inertia ixx="0.000245" ixy="0" ixz="0.0" iyy="0.000248" iyz="0" izz="0.000006"/>
        </inertial>
        <visual>
            <geometry>
                <mesh filename="../meshes/mini_lower_link.stl"/>
            </geometry>
            <origin rpy="0.0 3.141592 0.0" xyz="0.0 0.0 0.0"/>
        </visual>
        <collision>
            <geometry>
                <mesh filename="../meshes/mini_lower_link.stl"/>
            </geometry>
            <origin rpy="0 3.141592 0" xyz="0 0 0"/>
        </collision>
    </link>
    <link name="4_RL_foot">
        <visual>
        <origin rpy="0 0 0" xyz="0 0 0"/>
        <geometry>
            <sphere radius="0.015"/>
        </geometry>
        <material name="darkgray"/>
        </visual>
        <collision>
        <origin rpy="0 0 0" xyz="0 0 0"/>
        <geometry>
            <sphere radius="0.015"/>
        </geometry>
        </collision>
        <inertial>
        <mass value="0.15"/>
        <inertia ixx="0.000025" ixy="0" ixz="0" iyy="0.000025" iyz="0" izz="0.000025"/>
        </inertial>
    </link>
    <joint name="4_RL_foot_fixed" type="fixed" dont_collapse="true">
        <parent link="4_RL_calf"/>
        <child link="4_RL_foot"/>
        <origin xyz="0 0 -0.18"/>
        <dynamics damping="0.0" friction="0.0"/>
    </joint>

</robot>