<?xml version="1.0" encoding="utf-8"?>
 <!-- This URDF was automatically created by SolidWorks to URDF Exporter! Originally created by
 Stephen Brawner (brawner@gmail.com) 
      Commit Version: 1.6.0-4-g7f85cfe  Build Version: 1.6.7995.38578
      For more information, please see http://wiki.ros.org/sw_urdf_exporter -->
 <robot name="go2_description">
   <link name="base">
     <inertial>
       <origin xyz="0.021112 0 -0.005366" rpy="0 0 0" />
       <mass value="6.921" />
       <inertia ixx="0.02448" ixy="0.00012166" ixz="0.0014849" iyy="0.098077" iyz="-3.12E-05" izz="0.107" />
     </inertial>
     <visual>
       <origin xyz="0 0 0" rpy="0 0 0" />
       <geometry>
         <mesh filename="../meshes/trunk.dae" />
       </geometry>
       <material name="">
         <color rgba="1 1 1 1" />
       </material>
     </visual>
     <collision>
       <origin rpy="0 0 0" xyz="0 0 0" />
       <geometry>
         <box size="0.3762 0.0935 0.114" />
       </geometry>
     </collision>
   </link>
   <link name="Head_upper">
     <inertial>
       <origin xyz="0 0 0" rpy="0 0 0" />
       <mass value="0.001" />
       <inertia ixx="9.6e-06" ixy="0" ixz="0" iyy="9.6e-06" iyz="0" izz="9.6e-06" />
     </inertial>
     <collision>
       <origin xyz="0 0 0" rpy="0 0 0" />
       <geometry>
         <cylinder radius="0.05" length="0.09" />
       </geometry>
     </collision>
   </link>
   <joint name="Head_upper_joint" type="fixed" dont_collapse="true">
     <origin xyz="0.285 0 0.01" rpy="0 0 0" />
     <parent link="base" />
     <child link="Head_upper" />
     <axis xyz="0 0 0" />
   </joint>
   <link name="Head_lower">
     <inertial>
       <origin xyz="0 0 0" rpy="0 0 0" />
       <mass value="0.001" />
       <inertia ixx="9.6e-06" ixy="0" ixz="0" iyy="9.6e-06" iyz="0" izz="9.6e-06" />
     </inertial>
     <collision>
       <origin xyz="0 0 0" rpy="0 0 0" />
       <geometry>
         <sphere radius="0.047" />
       </geometry>
     </collision>
   </link>
   <joint name="Head_lower_joint" type="fixed" dont_collapse="true">
     <origin xyz="0.008 0 -0.07" rpy="0 0 0" />
     <parent link="Head_upper" />
     <child link="Head_lower" />
     <axis xyz="0 0 0" />
   </joint>
   <link name="2_FL_hip">
     <inertial>
       <origin xyz="-0.0054 0.00194 -0.000105" rpy="0 0 0" />
       <mass value="0.678" />
       <inertia ixx="0.00048" ixy="-3.01E-06" ixz="1.11E-06" iyy="0.000884" iyz="-1.42E-06" izz="0.000596" />
     </inertial>
     <visual>
       <origin xyz="0 0 0" rpy="0 0 0" />
       <geometry>
         <mesh filename="../meshes/hip.dae" />
       </geometry>
       <material name="">
         <color rgba="1 1 1 1" />
       </material>
     </visual>
     <collision>
       <origin rpy="1.5707963267948966 0 0" xyz="0 0.08 0" />
       <geometry>
         <cylinder length="0.04" radius="0.046" />
       </geometry>
     </collision>
   </link>
   <joint name="2_FL_hip_joint" type="revolute">
     <origin xyz="0.1934 0.0465 0" rpy="0 0 0" />
     <parent link="base" />
     <child link="2_FL_hip" />
     <axis xyz="1 0 0" />
     <limit lower="-1.0472" upper="1.0472" effort="23.7" velocity="30.1" />
   </joint>
   <link name="2_FL_hip_rotor">
     <inertial>
       <origin rpy="0 0 0" xyz="0.0 0.0 0.0"/>
       <mass value="0.089"/>
       <inertia ixx="0.000111842" ixy="0.0" ixz="0.0" iyy="0.000059647" iyz="0.0" izz="0.000059647"/>
     </inertial>
   </link>
   <joint name="2_FL_hip_rotor_joint" type="fixed">
     <origin rpy="0 0 0" xyz="0.11215 0.04675 0"/>
     <parent link="base"/>
     <child link="2_FL_hip_rotor"/>
   </joint>
   <link name="2_FL_thigh">
     <inertial>
       <origin xyz="-0.00374 -0.0223 -0.0327" rpy="0 0 0" />
       <mass value="1.152" />
       <inertia ixx="0.00584" ixy="8.72E-05" ixz="-0.000289" iyy="0.0058" iyz="0.000808" izz="0.00103" />
     </inertial>
     <visual>
       <origin xyz="0 0 0" rpy="0 0 0" />
       <geometry>
         <mesh filename="../meshes/thigh.dae" />
       </geometry>
       <material name="">
         <color rgba="1 1 1 1" />
       </material>
     </visual>
     <collision>
       <origin rpy="0 1.5707963267948966 0" xyz="0 0 -0.1065" />
       <geometry>
         <box size="0.213 0.0245 0.034" />
       </geometry>
     </collision>
   </link>
   <joint name="2_FL_thigh_joint" type="revolute">
     <origin xyz="0 0.0955 0" rpy="0 0 0" />
     <parent link="2_FL_hip" />
     <child link="2_FL_thigh" />
     <axis xyz="0 1 0" />
     <limit lower="-1.5708" upper="3.4907" effort="23.7" velocity="30.1" />
   </joint>
   <link name="2_FL_thigh_rotor">
     <inertial>
       <origin rpy="0 0 0" xyz="0.0 0.0 0.0"/>
       <mass value="0.089"/>
       <inertia ixx="0.000059647" ixy="0.0" ixz="0.0" iyy="0.000111842" iyz="0.0" izz="0.000059647"/>
     </inertial>
   </link>
   <joint name="2_FL_thigh_rotor_joint" type="fixed">
     <origin rpy="0 0 0" xyz="0 -0.00015 0"/>
     <parent link="2_FL_hip"/>
     <child link="2_FL_thigh_rotor"/>
   </joint>
   <link name="2_FL_calf">
     <inertial>
       <origin xyz="0.00548 -0.000975 -0.115" rpy="0 0 0" />
       <mass value="0.154" />
       <inertia ixx="0.00108" ixy="3.4E-07" ixz="1.72E-05" iyy="0.0011" iyz="8.28E-06" izz="3.29E-05" />
     </inertial>
     <visual>
       <origin xyz="0 0 0" rpy="0 0 0" />
       <geometry>
         <mesh filename="../meshes/calf.dae" />
       </geometry>
       <material name="">
         <color rgba="1 1 1 1" />
       </material>
     </visual>
     <collision>
       <origin rpy="0 -0.21 0" xyz="0.008 0 -0.06" />
       <geometry>
         <cylinder length="0.12" radius="0.012" />
       </geometry>
     </collision>
   </link>
   <joint name="2_FL_calf_joint" type="revolute">
     <origin xyz="0 0 -0.213" rpy="0 0 0" />
     <parent link="2_FL_thigh" />
     <child link="2_FL_calf" />
     <axis xyz="0 1 0" />
     <limit lower="-2.7227" upper="-0.83776" effort="45.43" velocity="15.70" />
   </joint>
   <link name="2_FL_calflower">
     <collision>
       <origin rpy="0 0 0" xyz="0 0 0" />
       <geometry>
         <cylinder length="0.065" radius="0.011" />
       </geometry>
     </collision>
   </link>
   <joint name="2_FL_calflower_joint" type="fixed">
     <origin xyz="0.020 0 -0.148" rpy="0 0.05 0" />
     <parent link="2_FL_calf" />
     <child link="2_FL_calflower" />
     <axis xyz="0 0 0" />
   </joint>
   <link name="2_FL_calflower1">
     <collision>
       <origin rpy="0 0 0" xyz="0 0 0" />
       <geometry>
         <cylinder length="0.03" radius="0.0155" />
       </geometry>
     </collision>
   </link>
   <joint name="2_FL_calflower1_joint" type="fixed">
     <origin xyz="-0.01 0 -0.04" rpy="0 0.48 0" />
     <parent link="2_FL_calflower" />
     <child link="2_FL_calflower1" />
     <axis xyz="0 0 0" />
   </joint>
   <link name="2_FL_calf_rotor">
     <inertial>
       <origin rpy="0 0 0" xyz="0.0 0.0 0.0"/>
       <mass value="0.089"/>
       <inertia ixx="0.000059647" ixy="0.0" ixz="0.0" iyy="0.000111842" iyz="0.0" izz="0.000059647"/>
     </inertial>
   </link>
   <joint name="2_FL_calf_rotor_joint" type="fixed">
     <origin rpy="0 0 0" xyz="0 -0.03235 0"/>
     <parent link="2_FL_thigh"/>
     <child link="2_FL_calf_rotor"/>
   </joint>
   <link name="2_FL_foot">
     <inertial>
       <origin xyz="0 0 0" rpy="0 0 0" />
       <mass value="0.04" />
       <inertia ixx="9.6e-06" ixy="0" ixz="0" iyy="9.6e-06" iyz="0" izz="9.6e-06" />
     </inertial>
     <visual>
       <origin xyz="0 0 0" rpy="0 0 0" />
       <geometry>
         <mesh filename="../meshes/foot.dae" />
       </geometry>
       <material name="">
         <color rgba="1 1 1 1" />
       </material>
     </visual>
     <collision>
       <origin rpy="0 0 0" xyz="-0.002 0 0" />
       <geometry>
         <sphere radius="0.022" />
       </geometry>
     </collision>
   </link>
   <joint name="2_FL_foot_joint" type="fixed" dont_collapse="true">
     <origin xyz="0 0 -0.213" rpy="0 0 0" />
     <parent link="2_FL_calf" />
     <child link="2_FL_foot" />
     <axis xyz="0 0 0" />
   </joint>
   <link name="1_FR_hip">
     <inertial>
       <origin xyz="-0.0054 -0.00194 -0.000105" rpy="0 0 0" />
       <mass value="0.678" />
       <inertia ixx="0.00048" ixy="3.01E-06" ixz="1.11E-06" iyy="0.000884" iyz="1.42E-06" izz="0.000596" />
     </inertial>
     <visual>
       <origin xyz="0 0 0" rpy="3.1415 0 0" />
       <geometry>
         <mesh filename="../meshes/hip.dae" />
       </geometry>
       <material name="">
         <color rgba="1 1 1 1" />
       </material>
     </visual>
     <collision>
       <origin rpy="1.5707963267948966 0 0" xyz="0 -0.08 0" />
       <geometry>
         <cylinder length="0.04" radius="0.046" />
       </geometry>
     </collision>
   </link>
   <joint name="1_FR_hip_joint" type="revolute">
     <origin xyz="0.1934 -0.0465 0" rpy="0 0 0" />
     <parent link="base" />
     <child link="1_FR_hip" />
     <axis xyz="1 0 0" />
     <limit lower="-1.0472" upper="1.0472" effort="23.7" velocity="30.1" />
   </joint>
   <link name="1_FR_hip_rotor">
     <inertial>
       <origin rpy="0 0 0" xyz="0.0 0.0 0.0"/>
       <mass value="0.089"/>
       <inertia ixx="0.000111842" ixy="0.0" ixz="0.0" iyy="0.000059647" iyz="0.0" izz="0.000059647"/>
     </inertial>
   </link>
   <joint name="1_FR_hip_rotor_joint" type="fixed">
     <origin rpy="0 0 0" xyz="0.11215 -0.04675 0"/>
     <parent link="base"/>
     <child link="1_FR_hip_rotor"/>
   </joint>
   <link name="1_FR_thigh">
     <inertial>
       <origin xyz="-0.00374 0.0223 -0.0327" rpy="0 0 0" />
       <mass value="1.152" />
       <inertia ixx="0.00584" ixy="-8.72E-05" ixz="-0.000289" iyy="0.0058" iyz="-0.000808" izz="0.00103" />
     </inertial>
     <visual>
       <origin xyz="0 0 0" rpy="0 0 0" />
       <geometry>
         <mesh filename="../meshes/thigh_mirror.dae" />
       </geometry>
       <material name="">
         <color rgba="1 1 1 1" />
       </material>
     </visual>
     <collision>
       <origin rpy="0 1.5707963267948966 0" xyz="0 0 -0.1065" />
       <geometry>
         <box size="0.213 0.0245 0.034" />
       </geometry>
     </collision>
   </link>
   <joint name="1_FR_thigh_joint" type="revolute">
     <origin xyz="0 -0.0955 0" rpy="0 0 0" />
     <parent link="1_FR_hip" />
     <child link="1_FR_thigh" />
     <axis xyz="0 1 0" />
     <limit lower="-1.5708" upper="3.4907" effort="23.7" velocity="30.1" />
   </joint>
   <link name="1_FR_thigh_rotor">
     <inertial>
       <origin rpy="0 0 0" xyz="0.0 0.0 0.0"/>
       <mass value="0.089"/>
       <inertia ixx="0.000059647" ixy="0.0" ixz="0.0" iyy="0.000111842" iyz="0.0" izz="0.000059647"/>
     </inertial>
   </link>
   <joint name="1_FR_thigh_rotor_joint" type="fixed">
     <origin rpy="0 0 0" xyz="0 0.00015 0"/>
     <parent link="1_FR_hip"/>
     <child link="1_FR_thigh_rotor"/>
   </joint>
   <link name="1_FR_calf">
     <inertial>
       <origin xyz="0.00548 0.000975 -0.115" rpy="0 0 0" />
       <mass value="0.154" />
       <inertia ixx="0.00108" ixy="-3.4E-07" ixz="1.72E-05" iyy="0.0011" iyz="-8.28E-06" izz="3.29E-05" />
     </inertial>
     <visual>
       <origin xyz="0 0 0" rpy="0 0 0" />
       <geometry>
         <mesh filename="../meshes/calf_mirror.dae" />
       </geometry>
       <material name="">
         <color rgba="1 1 1 1" />
       </material>
     </visual>
     <collision>
       <origin rpy="0 -0.2 0" xyz="0.01 0 -0.06" />
       <geometry>
         <cylinder length="0.12" radius="0.013" />
       </geometry>
     </collision>
   </link>
   <joint name="1_FR_calf_joint" type="revolute">
     <origin xyz="0 0 -0.213" rpy="0 0 0" />
     <parent link="1_FR_thigh" />
     <child link="1_FR_calf" />
     <axis xyz="0 1 0" />
     <limit lower="-2.7227" upper="-0.83776" effort="45.43" velocity="15.70" />
   </joint>
   <link name="1_FR_calflower">
     <collision>
       <origin rpy="0 0 0" xyz="0 0 0" />
       <geometry>
         <cylinder length="0.065" radius="0.011" />
       </geometry>
     </collision>
   </link>
   <joint name="1_FR_calflower_joint" type="fixed">
     <origin xyz="0.020 0 -0.148" rpy="0 0.05 0" />
     <parent link="1_FR_calf" />
     <child link="1_FR_calflower" />
     <axis xyz="0 0 0" />
   </joint>
   <link name="1_FR_calflower1">
     <collision>
       <origin rpy="0 0 0" xyz="0 0 0" />
       <geometry>
         <cylinder length="0.03" radius="0.0155" />
       </geometry>
     </collision>
   </link>
   <joint name="1_FR_calflower1_joint" type="fixed">
     <origin xyz="-0.01 0 -0.04" rpy="0 0.48 0" />
     <parent link="1_FR_calflower" />
     <child link="1_FR_calflower1" />
     <axis xyz="0 0 0" />
   </joint>
   <link name="1_FR_calf_rotor">
     <inertial>
       <origin rpy="0 0 0" xyz="0.0 0.0 0.0"/>
       <mass value="0.089"/>
       <inertia ixx="0.000059647" ixy="0.0" ixz="0.0" iyy="0.000111842" iyz="0.0" izz="0.000059647"/>
     </inertial>
   </link>
   <joint name="1_FR_calf_rotor_joint" type="fixed">
     <origin rpy="0 0 0" xyz="0 0.03235 0"/>
     <parent link="1_FR_thigh"/>
     <child link="1_FR_calf_rotor"/>
   </joint>
   <link name="1_FR_foot">
     <inertial>
       <origin xyz="0 0 0" rpy="0 0 0" />
       <mass value="0.04" />
       <inertia ixx="9.6e-06" ixy="0" ixz="0" iyy="9.6e-06" iyz="0" izz="9.6e-06" />
     </inertial>
     <visual>
       <origin xyz="0 0 0" rpy="0 0 0" />
       <geometry>
         <mesh filename="../meshes/foot.dae" />
       </geometry>
       <material name="">
         <color rgba="1 1 1 1" />
       </material>
     </visual>
     <collision>
       <origin rpy="0 0 0" xyz="-0.002 0 0" />
       <geometry>
         <sphere radius="0.022" />
       </geometry>
     </collision>
   </link>
   <joint name="1_FR_foot_joint" type="fixed" dont_collapse="true">
     <origin xyz="0 0 -0.213" rpy="0 0 0" />
     <parent link="1_FR_calf" />
     <child link="1_FR_foot" />
     <axis xyz="0 0 0" />
   </joint>
   <link name="4_RL_hip">
     <inertial>
       <origin xyz="0.0054 0.00194 -0.000105" rpy="0 0 0" />
       <mass value="0.678" />
       <inertia ixx="0.00048" ixy="3.01E-06" ixz="-1.11E-06" iyy="0.000884" iyz="-1.42E-06" izz="0.000596" />
     </inertial>
     <visual>
       <origin xyz="0 0 0" rpy="0 3.1415 0" />
       <geometry>
         <mesh filename="../meshes/hip.dae" />
       </geometry>
       <material name="">
         <color rgba="1 1 1 1" />
       </material>
     </visual>
     <collision>
       <origin rpy="1.5707963267948966 0 0" xyz="0 0.08 0" />
       <geometry>
         <cylinder length="0.04" radius="0.046" />
       </geometry>
     </collision>
   </link>
   <joint name="4_RL_hip_joint" type="revolute">
     <origin xyz="-0.1934 0.0465 0" rpy="0 0 0" />
     <parent link="base" />
     <child link="4_RL_hip" />
     <axis xyz="1 0 0" />
     <limit lower="-1.0472" upper="1.0472" effort="23.7" velocity="30.1" />
   </joint>
   <link name="4_RL_hip_rotor">
     <inertial>
       <origin rpy="0 0 0" xyz="0.0 0.0 0.0"/>
       <mass value="0.089"/>
       <inertia ixx="0.000111842" ixy="0.0" ixz="0.0" iyy="0.000059647" iyz="0.0" izz="0.000059647"/>
     </inertial>
   </link>
   <joint name="4_RL_hip_rotor_joint" type="fixed">
     <origin rpy="0 0 0" xyz="-0.11215 0.04675 0"/>
     <parent link="base"/>
     <child link="4_RL_hip_rotor"/>
   </joint>
   <link name="4_RL_thigh">
     <inertial>
       <origin xyz="-0.00374 -0.0223 -0.0327" rpy="0 0 0" />
       <mass value="1.152" />
       <inertia ixx="0.00584" ixy="8.72E-05" ixz="-0.000289" iyy="0.0058" iyz="0.000808" izz="0.00103" />
     </inertial>
     <visual>
       <origin xyz="0 0 0" rpy="0 0 0" />
       <geometry>
         <mesh filename="../meshes/thigh.dae" />
       </geometry>
       <material name="">
         <color rgba="1 1 1 1" />
       </material>
     </visual>
     <collision>
       <origin rpy="0 1.5707963267948966 0" xyz="0 0 -0.1065" />
       <geometry>
         <box size="0.213 0.0245 0.034" />
       </geometry>
     </collision>
   </link>
   <joint name="4_RL_thigh_joint" type="revolute">
     <origin xyz="0 0.0955 0" rpy="0 0 0" />
     <parent link="4_RL_hip" />
     <child link="4_RL_thigh" />
     <axis xyz="0 1 0" />
     <limit lower="-0.5236" upper="4.5379" effort="23.7" velocity="30.1" />
   </joint>
   <link name="4_RL_thigh_rotor">
     <inertial>
       <origin rpy="0 0 0" xyz="0.0 0.0 0.0"/>
       <mass value="0.089"/>
       <inertia ixx="0.000059647" ixy="0.0" ixz="0.0" iyy="0.000111842" iyz="0.0" izz="0.000059647"/>
     </inertial>
   </link>
   <joint name="4_RL_thigh_rotor_joint" type="fixed">
     <origin rpy="0 0 0" xyz="0 -0.00015 0"/>
     <parent link="4_RL_hip"/>
     <child link="4_RL_thigh_rotor"/>
   </joint>
   <link name="4_RL_calf">
     <inertial>
       <origin xyz="0.00548 -0.000975 -0.115" rpy="0 0 0" />
       <mass value="0.154" />
       <inertia ixx="0.00108" ixy="3.4E-07" ixz="1.72E-05" iyy="0.0011" iyz="8.28E-06" izz="3.29E-05" />
     </inertial>
     <visual>
       <origin xyz="0 0 0" rpy="0 0 0" />
       <geometry>
         <mesh filename="../meshes/calf.dae" />
       </geometry>
       <material name="">
         <color rgba="1 1 1 1" />
       </material>
     </visual>
     <collision>
       <origin rpy="0 -0.2 0" xyz="0.01 0 -0.06" />
       <geometry>
         <cylinder length="0.12" radius="0.013" />
       </geometry>
     </collision>
   </link>
   <joint name="4_RL_calf_joint" type="revolute">
     <origin xyz="0 0 -0.213" rpy="0 0 0" />
     <parent link="4_RL_thigh" />
     <child link="4_RL_calf" />
     <axis xyz="0 1 0" />
     <limit lower="-2.7227" upper="-0.83776" effort="45.43" velocity="15.70" />
   </joint>
   <link name="4_RL_calflower">
     <collision>
       <origin rpy="0 0 0" xyz="0 0 0" />
       <geometry>
         <cylinder length="0.065" radius="0.011" />
       </geometry>
     </collision>
   </link>
   <joint name="4_RL_calflower_joint" type="fixed">
     <origin xyz="0.020 0 -0.148" rpy="0 0.05 0" />
     <parent link="4_RL_calf" />
     <child link="4_RL_calflower" />
     <axis xyz="0 0 0" />
   </joint>
   <link name="4_RL_calflower1">
     <collision>
       <origin rpy="0 0 0" xyz="0 0 0" />
       <geometry>
         <cylinder length="0.03" radius="0.0155" />
       </geometry>
     </collision>
   </link>
   <joint name="4_RL_calflower1_joint" type="fixed">
     <origin xyz="-0.01 0 -0.04" rpy="0 0.48 0" />
     <parent link="4_RL_calflower" />
     <child link="4_RL_calflower1" />
     <axis xyz="0 0 0" />
   </joint>
   <link name="4_RL_calf_rotor">
     <inertial>
       <origin rpy="0 0 0" xyz="0.0 0.0 0.0"/>
       <mass value="0.089"/>
       <inertia ixx="0.000059647" ixy="0.0" ixz="0.0" iyy="0.000111842" iyz="0.0" izz="0.000059647"/>
     </inertial>
   </link>
   <joint name="4_RL_calf_rotor_joint" type="fixed">
     <origin rpy="0 0 0" xyz="0 -0.03235 0"/>
     <parent link="4_RL_thigh"/>
     <child link="4_RL_calf_rotor"/>
   </joint>
   <link name="4_RL_foot">
     <inertial>
       <origin xyz="0 0 0" rpy="0 0 0" />
       <mass value="0.04" />
       <inertia ixx="9.6e-06" ixy="0" ixz="0" iyy="9.6e-06" iyz="0" izz="9.6e-06" />
     </inertial>
     <visual>
       <origin xyz="0 0 0" rpy="0 0 0" />
       <geometry>
         <mesh filename="../meshes/foot.dae" />
       </geometry>
       <material name="">
         <color rgba="1 1 1 1" />
       </material>
     </visual>
     <collision>
       <origin rpy="0 0 0" xyz="-0.002 0 0" />
       <geometry>
         <sphere radius="0.022" />
       </geometry>
     </collision>
   </link>
   <joint name="4_RL_foot_joint" type="fixed" dont_collapse="true">
     <origin xyz="0 0 -0.213" rpy="0 0 0" />
     <parent link="4_RL_calf" />
     <child link="4_RL_foot" />
     <axis xyz="0 0 0" />
   </joint>
   <link name="3_RR_hip">
     <inertial>
       <origin xyz="0.0054 -0.00194 -0.000105" rpy="0 0 0" />
       <mass value="0.678" />
       <inertia ixx="0.00048" ixy="-3.01E-06" ixz="-1.11E-06" iyy="0.000884" iyz="1.42E-06" izz="0.000596" />
     </inertial>
     <visual>
       <origin xyz="0 0 0" rpy="3.1415 3.1415 0" />
       <geometry>
         <mesh filename="../meshes/hip.dae" />
       </geometry>
       <material name="">
         <color rgba="1 1 1 1" />
       </material>
     </visual>
     <collision>
       <origin rpy="1.5707963267948966 0 0" xyz="0 -0.08 0" />
       <geometry>
         <cylinder length="0.04" radius="0.046" />
       </geometry>
     </collision>
   </link>
   <joint name="3_RR_hip_joint" type="revolute">
     <origin xyz="-0.1934 -0.0465 0" rpy="0 0 0" />
     <parent link="base" />
     <child link="3_RR_hip" />
     <axis xyz="1 0 0" />
     <limit lower="-1.0472" upper="1.0472" effort="23.7" velocity="30.1" />
   </joint>
   <link name="3_RR_hip_rotor">
     <inertial>
       <origin rpy="0 0 0" xyz="0.0 0.0 0.0"/>
       <mass value="0.089"/>
       <inertia ixx="0.000111842" ixy="0.0" ixz="0.0" iyy="0.000059647" iyz="0.0" izz="0.000059647"/>
     </inertial>
   </link>
   <joint name="3_RR_hip_rotor_joint" type="fixed">
     <origin rpy="0 0 0" xyz="-0.11215 -0.04675 0"/>
     <parent link="base"/>
     <child link="3_RR_hip_rotor"/>
   </joint>
   <link name="3_RR_thigh">
     <inertial>
       <origin xyz="-0.00374 0.0223 -0.0327" rpy="0 0 0" />
       <mass value="1.152" />
       <inertia ixx="0.00584" ixy="-8.72E-05" ixz="-0.000289" iyy="0.0058" iyz="-0.000808" izz="0.00103" />
     </inertial>
     <visual>
       <origin xyz="0 0 0" rpy="0 0 0" />
       <geometry>
         <mesh filename="../meshes/thigh_mirror.dae" />
       </geometry>
       <material name="">
         <color rgba="1 1 1 1" />
       </material>
     </visual>
     <collision>
       <origin rpy="0 1.5707963267948966 0" xyz="0 0 -0.1065" />
       <geometry>
         <box size="0.213 0.0245 0.034" />
       </geometry>
     </collision>
   </link>
   <joint name="3_RR_thigh_joint" type="revolute">
     <origin xyz="0 -0.0955 0" rpy="0 0 0" />
     <parent link="3_RR_hip" />
     <child link="3_RR_thigh" />
     <axis xyz="0 1 0" />
     <limit lower="-0.5236" upper="4.5379" effort="23.7" velocity="30.1" />
   </joint>
   <link name="3_RR_thigh_rotor">
     <inertial>
       <origin rpy="0 0 0" xyz="0.0 0.0 0.0"/>
       <mass value="0.089"/>
       <inertia ixx="0.000059647" ixy="0.0" ixz="0.0" iyy="0.000111842" iyz="0.0" izz="0.000059647"/>
     </inertial>
   </link>
   <joint name="3_RR_thigh_rotor_joint" type="fixed">
     <origin rpy="0 0 0" xyz="0 0.00015 0"/>
     <parent link="3_RR_hip"/>
     <child link="3_RR_thigh_rotor"/>
   </joint>
   <link name="3_RR_calf">
     <inertial>
       <origin xyz="0.00548 0.000975 -0.115" rpy="0 0 0" />
       <mass value="0.154" />
       <inertia ixx="0.00108" ixy="-3.4E-07" ixz="1.72E-05" iyy="0.0011" iyz="-8.28E-06" izz="3.29E-05" />
     </inertial>
     <visual>
       <origin xyz="0 0 0" rpy="0 0 0" />
       <geometry>
         <mesh filename="../meshes/calf_mirror.dae" />
       </geometry>
       <material name="">
         <color rgba="1 1 1 1" />
       </material>
     </visual>
     <collision>
       <origin rpy="0 -0.2 0" xyz="0.01 0 -0.06" />
       <geometry>
         <cylinder length="0.12" radius="0.013" />
       </geometry>
     </collision>
   </link>
   <joint name="3_RR_calf_joint" type="revolute">
     <origin xyz="0 0 -0.213" rpy="0 0 0" />
     <parent link="3_RR_thigh" />
     <child link="3_RR_calf" />
     <axis xyz="0 1 0" />
     <limit lower="-2.7227" upper="-0.83776" effort="45.43" velocity="15.70" />
   </joint>
   <link name="3_RR_calflower">
     <collision>
       <origin rpy="0 0 0" xyz="0 0 0" />
       <geometry>
         <cylinder length="0.065" radius="0.011" />
       </geometry>
     </collision>
   </link>
   <joint name="3_RR_calflower_joint" type="fixed">
     <origin xyz="0.020 0 -0.148" rpy="0 0.05 0" />
     <parent link="3_RR_calf" />
     <child link="3_RR_calflower" />
     <axis xyz="0 0 0" />
   </joint>
   <link name="3_RR_calflower1">
     <collision>
       <origin rpy="0 0 0" xyz="0 0 0" />
       <geometry>
         <cylinder length="0.03" radius="0.0155" />
       </geometry>
     </collision>
   </link>
   <joint name="3_RR_calflower1_joint" type="fixed">
     <origin xyz="-0.01 0 -0.04" rpy="0 0.48 0" />
     <parent link="3_RR_calflower" />
     <child link="3_RR_calflower1" />
     <axis xyz="0 0 0" />
   </joint>
   <link name="3_RR_calf_rotor">
     <inertial>
       <origin rpy="0 0 0" xyz="0.0 0.0 0.0"/>
       <mass value="0.089"/>
       <inertia ixx="0.000059647" ixy="0.0" ixz="0.0" iyy="0.000111842" iyz="0.0" izz="0.000059647"/>
     </inertial>
   </link>
   <joint name="3_RR_calf_rotor_joint" type="fixed">
     <origin rpy="0 0 0" xyz="0 0.03235 0"/>
     <parent link="3_RR_thigh"/>
     <child link="3_RR_calf_rotor"/>
   </joint>
   <link name="3_RR_foot">
     <inertial>
       <origin xyz="0 0 0" rpy="0 0 0" />
       <mass value="0.04" />
       <inertia ixx="9.6e-06" ixy="0" ixz="0" iyy="9.6e-06" iyz="0" izz="9.6e-06" />
     </inertial>
     <visual>
       <origin xyz="0 0 0" rpy="0 0 0" />
       <geometry>
         <mesh filename="../meshes/foot.dae" />
       </geometry>
       <material name="">
         <color rgba="1 1 1 1" />
       </material>
     </visual>
     <collision>
       <origin rpy="0 0 0" xyz="-0.002 0 0" />
       <geometry>
         <sphere radius="0.022" />
       </geometry>
     </collision>
   </link>
   <joint name="3_RR_foot_joint" type="fixed" dont_collapse="true">
     <origin xyz="0 0 -0.213" rpy="0 0 0" />
     <parent link="3_RR_calf" />
     <child link="3_RR_foot" />
     <axis xyz="0 0 0" />
   </joint>
   <link name="imu">
     <inertial>
       <origin xyz="0 0 0" rpy="0 0 0" />
       <mass value="0" />
       <inertia ixx="0" ixy="0" ixz="0" iyy="0" iyz="0" izz="0" />
     </inertial>
   </link>
   <joint name="imu_joint" type="fixed">
     <origin xyz="-0.02557 0 0.04232" rpy="0 0 0" />
     <parent link="base" />
     <child link="imu" />
     <axis xyz="0 0 0" />
   </joint>
   <link name="radar">
     <inertial>
       <origin xyz="0 0 0" rpy="0 0 0" />
       <mass value="0" />
       <inertia ixx="0" ixy="0" ixz="0" iyy="0" iyz="0" izz="0" />
     </inertial>
   </link>
   <joint name="radar_joint" type="fixed">
     <origin xyz="0.28945 0 -0.046825" rpy="0 2.8782 0" />
     <parent link="base" />
     <child link="radar" />
     <axis xyz="0 0 0" />
   </joint>
   <joint name="front_camera_joint" type="fixed">
     <origin rpy="0 0 0" xyz="0.32715 -0.00003 0.04297"/>
       <parent link="base"/>
       <child link="front_camera"/>
   </joint>
   <link name="front_camera">
   </link>
 </robot>